<?xml version="1.0"?>
<robot xmlns:xacro="http://www.ros.org/wiki/xacro" name="myrobot">
	<link name="base_link">
                <visual>
                <origin rpy="0 0 0" xyz="0 0 0" />
                <geometry>
                <box size="1 1 1"/>
                </geometry>
                <material name="blue"/>
                </visual>
	</link>

        <joint name="base_link__link01" type="revolute">
                <axis xyz="0 0 1"/>
                <limit effort = "1000.0" lower="-3.14" upper="3.14" velocity="0.5"/>
                <origin rpy="0 0 0" xyz="0 0 0.5"/>
                <parent link="base_link"/>
                <child link="link_01"/>
        </joint>

        <link name="link_01">
                <visual>
                <origin rpy="0 0 0" xyz="0 1 0" />
                <geometry>
                <box size="1 2 0.1"/>
                </geometry>
                <material name="red"/>
                </visual>
        </link>
</robot>
